<mujoco model="ant">
  <compiler angle="radian" coordinate="local" inertiafromgeom="true"/>
  <option integrator="RK4" timestep="0.01"/>
    <size nconmax="500"/>
  <custom>
    <numeric data="0.0 0.0 0.55 1.0 0.0 0.0 0.0 0.0 1.0 0.0 -1.0 0.0 -1.0 0.0 1.0" name="init_qpos"/>
  </custom>
  <default>
    <joint armature="1" damping="1" limited="true"/>
    <geom conaffinity="0" condim="3" density="5.0" friction="1 0.5 0.5" margin="0.01" rgba="0.8 0.6 0.4 1"/>
  </default>
  <asset>
    <texture builtin="gradient" height="100" rgb1="1 1 1" rgb2="0 0 0" type="skybox" width="100"/>
    <texture builtin="flat" height="1278" mark="cross" markrgb="1 1 1" name="texgeom" random="0.01" rgb1="0.8 0.6 0.4" rgb2="0.8 0.6 0.4" type="cube" width="127"/>
    <texture builtin="checker" height="100" name="texplane" rgb1="0 0 0" rgb2="0.8 0.8 0.8" type="2d" width="100"/>
    <material name="MatPlane" reflectance="0.2" shininess="1" specular="1" texrepeat="0 0" texture="texplane"/>
    <material name="geom" texture="texgeom" texuniform="true"/>
  </asset>

  <worldbody>
    <light cutoff="100" diffuse="1 1 1" dir="-0 0 -1.3" directional="true" exponent="1" pos="0 0 1.3" specular=".1 .1 .1"/>
    <geom conaffinity="1" condim="3" material="MatPlane" name="floor" pos="0 0 0" rgba="0.8 0.9 0.8 1" size="10 10 1" type="plane"/>

    <body name="torso" pos="0 0 0.75">
      <camera name="track" mode="trackcom" pos="0 -3 0.3" xyaxes="1 0 0 0 0 1"/>
      <geom name="torso_geom" pos="0 0 0" size="0.25" mass="0.1" type="sphere"/>
      <joint armature="0" damping="0" limited="false" margin="0.01" name="root" pos="0 0 0" type="free"/>

      <body name="front_left_leg" pos="0 0 0">
        <geom fromto="0.0 0.0 0.0 0.2 0.2 0.0" name="aux_1_geom" size="0.08" type="capsule"/>
        <body name="aux_1" pos="0.2 0.2 0">
          <joint axis="0 0 1" name="hip_1" pos="0.0 0.0 0.0" range="-0.7 0.7" type="hinge"/>
          <geom fromto="0.0 0.0 0.0 0.2 0.2 0.0" name="left_leg_geom" size="0.08" type="capsule"/>
          <body pos="0.2 0.2 0">
            <joint axis="-1 1 0" name="ankle_1" pos="0.0 0.0 0.0" range="0.8 1.4" type="hinge"/>
            <geom fromto="0.0 0.0 0.0 0.4 0.4 0.0" name="left_ankle_geom" size="0.08" type="capsule"/>
          </body>
        </body>
      </body>

      <body name="front_right_leg" pos="0 0 0">
        <geom fromto="0.0 0.0 0.0 -0.2 0.2 0.0" name="aux_2_geom" size="0.08" type="capsule"/>
        <body name="aux_2" pos="-0.2 0.2 0">
          <joint axis="0 0 1" name="hip_2" pos="0.0 0.0 0.0" range="-0.7 0.7" type="hinge"/>
          <geom fromto="0.0 0.0 0.0 -0.2 0.2 0.0" name="right_leg_geom" size="0.08" type="capsule"/>
          <body pos="-0.2 0.2 0">
            <joint axis="1 1 0" name="ankle_2" pos="0.0 0.0 0.0" range="-1.4 -0.8" type="hinge"/>
            <geom fromto="0.0 0.0 0.0 -0.4 0.4 0.0" name="right_ankle_geom" size="0.08" type="capsule"/>
          </body>
        </body>
      </body>

      <body name="back_leg" pos="0 0 0">
        <geom fromto="0.0 0.0 0.0 -0.2 -0.2 0.0" name="aux_3_geom" size="0.08" type="capsule"/>
        <body name="aux_3" pos="-0.2 -0.2 0">
          <joint axis="0 0 1" name="hip_3" pos="0.0 0.0 0.0" range="-0.7 0.7" type="hinge"/>
          <geom fromto="0.0 0.0 0.0 -0.2 -0.2 0.0" name="back_leg_geom" size="0.08" type="capsule"/>
          <body pos="-0.2 -0.2 0">
            <joint axis="-1 1 0" name="ankle_3" pos="0.0 0.0 0.0" range="-1.4 -0.8" type="hinge"/>
            <geom fromto="0.0 0.0 0.0 -0.4 -0.4 0.0" name="third_ankle_geom" size="0.08" type="capsule"/>
          </body>
        </body>
      </body>

      <body name="right_back_leg" pos="0 0 0">
        <geom fromto="0.0 0.0 0.0 0.2 -0.2 0.0" name="aux_4_geom" size="0.08" type="capsule"/>
        <body name="aux_4" pos="0.2 -0.2 0">
          <joint axis="0 0 1" name="hip_4" pos="0.0 0.0 0.0" range="-0.7 0.7" type="hinge"/>
          <geom fromto="0.0 0.0 0.0 0.2 -0.2 0.0" name="rightback_leg_geom" size="0.08" type="capsule"/>
          <body pos="0.2 -0.2 0">
            <joint axis="1 1 0" name="ankle_4" pos="0.0 0.0 0.0" range="0.8 1.4" type="hinge"/>
            <geom fromto="0.0 0.0 0.0 0.4 -0.4 0.0" name="fourth_ankle_geom" size="0.08" type="capsule"/>
          </body>
        </body>
      </body>

      <body name="left_feeler" pos="0 0 0">
        <joint axis="0 0 1" name="lf1" pos="0.0 0.0 0.0" range="0.08 0.3" type="hinge"/>
        <geom fromto="0.2 0.0 0.0 0.6 0.0 0.0" name="lf1_geom" size="0.01" density="1" type="capsule" rgba="0 1 1 1"/>
        <body pos="0.6 0.0 0">
          <joint axis="0 1 0" name="lf2" pos="0.0 0.0 0.0" range="-0.65 0.3" type="hinge"/>
          <geom fromto="0.0 0.0 0.0 0.6 0.0 0.0" name="lf2_geom" size="0.01" density="1" type="capsule" rgba="0 1 1 1"/>
        </body>
      </body>

      <body name="right_feeler" pos="0 0 0">
        <joint axis="0 0 1" name="rf1" pos="0.0 0.0 0.0" range="-0.3 -0.08" type="hinge"/>
        <geom fromto="0.2 0.0 0.0 0.6 0.0 0.0" name="rf1_geom" size="0.01" density="1" type="capsule" rgba="0 1 1 1"/>
        <body pos="0.6 0.0 0">
          <joint axis="0 1 0" name="rf2" pos="0.0 0.0 0.0" range="-0.65 0.3" type="hinge"/>
          <geom fromto="0.0 0.0 0.0 0.6 0.0 0.0" name="rf2_geom" size="0.01" density="1" type="capsule" rgba="0 1 1 1"/>
        </body>
      </body>

    </body>


<!-- DEFINE CUBES AND GOAL HERE -->
    <body> 
        <geom conaffinity='1' condim='3' name='cube0_geom' pos='-6.36790857739471 -5.9039342813488584 0.6' size='0.4120303950584243 0.5161234146401933 0.6' rgba='1 1 1 1' mass='70' type='box'/>
     </body> 
    <body> 
        <geom conaffinity='1' condim='3' name='cube1_geom' pos='-7.147908149552006 -1.8964377024366814 0.6' size='0.5166456681131799 0.48450718485857097 0.6' rgba='1 1 1 1' mass='70' type='box'/>
     </body> 
    <body> 
        <geom conaffinity='1' condim='3' name='cube2_geom' pos='-4.71169869613418 -0.5603639508621308 0.6' size='0.4764295498097667 0.4619846739929098 0.6' rgba='1 1 1 1' mass='70' type='box'/>
     </body> 
    <body> 
        <geom conaffinity='1' condim='3' name='cube3_geom' pos='-5.609842685481709 1.9711993673154895 0.6' size='0.33234198497878076 0.3974853184323799 0.6' rgba='1 1 1 1' mass='70' type='box'/>
     </body> 
    <body> 
        <geom conaffinity='1' condim='3' name='cube4_geom' pos='-4.79314034926213 6.803047085267689 0.6' size='0.5399586506721307 0.49705579038566233 0.6' rgba='1 1 1 1' mass='70' type='box'/>
     </body> 
    <body> 
        <geom conaffinity='1' condim='3' name='cube5_geom' pos='-2.157405350516927 -7.4635747200743445 0.6' size='0.40571246490126484 0.4577214139917618 0.6' rgba='1 1 1 1' mass='70' type='box'/>
     </body> 
    <body> 
        <geom conaffinity='1' condim='3' name='cube6_geom' pos='-1.5467816025738466 -4.267948420648551 0.6' size='0.40744418771108604 0.38169846051969397 0.6' rgba='1 1 1 1' mass='70' type='box'/>
     </body> 
    <body> 
        <geom conaffinity='1' condim='3' name='cube7_geom' pos='-4.335757580325867 1.0961208655122494 0.6' size='0.545132984797696 0.4310872623908638 0.6' rgba='1 1 1 1' mass='70' type='box'/>
     </body> 
    <body> 
        <geom conaffinity='1' condim='3' name='cube8_geom' pos='-3.7150886327379062 1.8339706523575003 0.6' size='0.463305065538416 0.3633444205756711 0.6' rgba='1 1 1 1' mass='70' type='box'/>
     </body> 
    <body> 
        <geom conaffinity='1' condim='3' name='cube9_geom' pos='-3.7093950029340546 6.527210488669157 0.6' size='0.5402460099531732 0.4877790897734522 0.6' rgba='1 1 1 1' mass='70' type='box'/>
     </body> 
    <body> 
        <geom conaffinity='1' condim='3' name='cube10_geom' pos='-0.13363934583185655 -6.999318645344814 0.6' size='0.6066542885197697 0.3894311409951079 0.6' rgba='1 1 1 1' mass='70' type='box'/>
     </body> 
    <body> 
        <geom conaffinity='1' condim='3' name='cube11_geom' pos='1.3382127359135136 -3.729592656399337 0.6' size='0.5623518921207891 0.4096799971529087 0.6' rgba='1 1 1 1' mass='70' type='box'/>
     </body> 
    <body> 
        <geom conaffinity='1' condim='3' name='cube12_geom' pos='0.0864291880691348 -1.2211639482058174 0.6' size='0.34859356550538534 0.3760185907845284 0.6' rgba='1 1 1 1' mass='70' type='box'/>
     </body> 
    <body> 
        <geom conaffinity='1' condim='3' name='cube13_geom' pos='1.2808864501589357 2.1231221079705174 0.6' size='0.4293183890539611 0.4455729204083325 0.6' rgba='1 1 1 1' mass='70' type='box'/>
     </body> 
    <body> 
        <geom conaffinity='1' condim='3' name='cube14_geom' pos='-0.9822757320484204 5.231174690062342 0.6' size='0.6181096565605915 0.35871367051048275 0.6' rgba='1 1 1 1' mass='70' type='box'/>
     </body> 
    <body> 
        <geom conaffinity='1' condim='3' name='cube15_geom' pos='1.8053099290863424 -7.108795669183058 0.6' size='0.36468101680201676 0.36834897627219954 0.6' rgba='1 1 1 1' mass='70' type='box'/>
     </body> 
    <body> 
        <geom conaffinity='1' condim='3' name='cube16_geom' pos='2.7462557263856926 -2.1253988793354868 0.6' size='0.38012174495950135 0.3040875800278948 0.6' rgba='1 1 1 1' mass='70' type='box'/>
     </body> 
    <body> 
        <geom conaffinity='1' condim='3' name='cube17_geom' pos='2.185967573567612 0.10266704686824135 0.6' size='0.3586090245527257 0.4514017667473171 0.6' rgba='1 1 1 1' mass='70' type='box'/>
     </body> 
    <body> 
        <geom conaffinity='1' condim='3' name='cube18_geom' pos='2.07616507724718 4.213236678357294 0.6' size='0.5429391355175719 0.5047478414059559 0.6' rgba='1 1 1 1' mass='70' type='box'/>
     </body> 
    <body> 
        <geom conaffinity='1' condim='3' name='cube19_geom' pos='1.8624202180706817 4.844294571095137 0.6' size='0.5804011640512312 0.5748272617700527 0.6' rgba='1 1 1 1' mass='70' type='box'/>
     </body> 
    <body> 
        <geom conaffinity='1' condim='3' name='cube20_geom' pos='6.217227758554621 -6.406419444748847 0.6' size='0.43201956077354375 0.41156770751945304 0.6' rgba='1 1 1 1' mass='70' type='box'/>
     </body> 
    <body> 
        <geom conaffinity='1' condim='3' name='cube21_geom' pos='4.861238321612113 -2.8412709462195576 0.6' size='0.5425298036287184 0.49287855861316915 0.6' rgba='1 1 1 1' mass='70' type='box'/>
     </body> 
    <body> 
        <geom conaffinity='1' condim='3' name='cube22_geom' pos='4.514224055478387 -1.1575906023866083 0.6' size='0.5828152464342302 0.6285091785398428 0.6' rgba='1 1 1 1' mass='70' type='box'/>
     </body> 
    <body> 
        <geom conaffinity='1' condim='3' name='cube23_geom' pos='4.769297274389615 2.5681009422050964 0.6' size='0.6135867965736845 0.45153191228570305 0.6' rgba='1 1 1 1' mass='70' type='box'/>
     </body> 
    <body> 
        <geom conaffinity='1' condim='3' name='cube24_geom' pos='7.408097626579954 6.85305953747541 0.6' size='0.5636516049330355 0.39692627147181236 0.6' rgba='1 1 1 1' mass='70' type='box'/>
     </body> 
    <body> 
        <geom conaffinity='1' condim='3' name='goal_geom' pos='2.6518359450566034 2.351206408428366 0.6' size='0.3' rgba='1 0 0 1' mass='1' type='sphere'/>
     </body> 



  </worldbody>

  <actuator>
    <position joint="hip_4" kp="20"/>
    <position joint="ankle_4" kp="20"/>
    <position joint="hip_1" kp="20"/>
    <position joint="ankle_1" kp="20"/>
    <position joint="hip_2" kp="20"/>
    <position joint="ankle_2" kp="20"/>
    <position joint="hip_3" kp="20"/>
    <position joint="ankle_3" kp="20"/>
    <motor ctrllimited="true" ctrlrange="-1.0 1.0" joint="lf1" gear="20"/>
    <motor ctrllimited="true" ctrlrange="-1.0 1.0" joint="lf2" gear="20"/>
    <motor ctrllimited="true" ctrlrange="-1.0 1.0" joint="rf1" gear="20"/>
    <motor ctrllimited="true" ctrlrange="-1.0 1.0" joint="rf2" gear="20"/>
  </actuator>
</mujoco>
