<mujoco model="ant">
  <compiler angle="radian" coordinate="local" inertiafromgeom="true"/>
  <option integrator="RK4" timestep="0.01"/>
    <size nconmax="500"/>
  <custom>
    <numeric data="0.0 0.0 0.55 1.0 0.0 0.0 0.0 0.0 1.0 0.0 -1.0 0.0 -1.0 0.0 1.0" name="init_qpos"/>
  </custom>
  <default>
    <joint armature="1" damping="1" limited="true"/>
    <geom conaffinity="0" condim="3" density="5.0" friction="1 0.5 0.5" margin="0.01" rgba="0.8 0.6 0.4 1"/>
  </default>
  <asset>
    <texture builtin="gradient" height="100" rgb1="1 1 1" rgb2="0 0 0" type="skybox" width="100"/>
    <texture builtin="flat" height="1278" mark="cross" markrgb="1 1 1" name="texgeom" random="0.01" rgb1="0.8 0.6 0.4" rgb2="0.8 0.6 0.4" type="cube" width="127"/>
    <texture builtin="checker" height="100" name="texplane" rgb1="0 0 0" rgb2="0.8 0.8 0.8" type="2d" width="100"/>
    <material name="MatPlane" reflectance="0.2" shininess="1" specular="1" texrepeat="0 0" texture="texplane"/>
    <material name="geom" texture="texgeom" texuniform="true"/>
  </asset>

  <worldbody>
    <light cutoff="100" diffuse="1 1 1" dir="-0 0 -1.3" directional="true" exponent="1" pos="0 0 1.3" specular=".1 .1 .1"/>
    <geom conaffinity="1" condim="3" material="MatPlane" name="floor" pos="0 0 0" rgba="0.8 0.9 0.8 1" size="10 10 1" type="plane"/>

    <body name="torso" pos="0 0 0.75">
      <camera name="track" mode="trackcom" pos="0 -3 0.3" xyaxes="1 0 0 0 0 1"/>
      <geom name="torso_geom" pos="0 0 0" size="0.25" mass="0.1" type="sphere"/>
      <joint armature="0" damping="0" limited="false" margin="0.01" name="root" pos="0 0 0" type="free"/>

      <body name="front_left_leg" pos="0 0 0">
        <geom fromto="0.0 0.0 0.0 0.2 0.2 0.0" name="aux_1_geom" size="0.08" type="capsule"/>
        <body name="aux_1" pos="0.2 0.2 0">
          <joint axis="0 0 1" name="hip_1" pos="0.0 0.0 0.0" range="-0.7 0.7" type="hinge"/>
          <geom fromto="0.0 0.0 0.0 0.2 0.2 0.0" name="left_leg_geom" size="0.08" type="capsule"/>
          <body pos="0.2 0.2 0">
            <joint axis="-1 1 0" name="ankle_1" pos="0.0 0.0 0.0" range="0.8 1.4" type="hinge"/>
            <geom fromto="0.0 0.0 0.0 0.4 0.4 0.0" name="left_ankle_geom" size="0.08" type="capsule"/>
          </body>
        </body>
      </body>

      <body name="front_right_leg" pos="0 0 0">
        <geom fromto="0.0 0.0 0.0 -0.2 0.2 0.0" name="aux_2_geom" size="0.08" type="capsule"/>
        <body name="aux_2" pos="-0.2 0.2 0">
          <joint axis="0 0 1" name="hip_2" pos="0.0 0.0 0.0" range="-0.7 0.7" type="hinge"/>
          <geom fromto="0.0 0.0 0.0 -0.2 0.2 0.0" name="right_leg_geom" size="0.08" type="capsule"/>
          <body pos="-0.2 0.2 0">
            <joint axis="1 1 0" name="ankle_2" pos="0.0 0.0 0.0" range="-1.4 -0.8" type="hinge"/>
            <geom fromto="0.0 0.0 0.0 -0.4 0.4 0.0" name="right_ankle_geom" size="0.08" type="capsule"/>
          </body>
        </body>
      </body>

      <body name="back_leg" pos="0 0 0">
        <geom fromto="0.0 0.0 0.0 -0.2 -0.2 0.0" name="aux_3_geom" size="0.08" type="capsule"/>
        <body name="aux_3" pos="-0.2 -0.2 0">
          <joint axis="0 0 1" name="hip_3" pos="0.0 0.0 0.0" range="-0.7 0.7" type="hinge"/>
          <geom fromto="0.0 0.0 0.0 -0.2 -0.2 0.0" name="back_leg_geom" size="0.08" type="capsule"/>
          <body pos="-0.2 -0.2 0">
            <joint axis="-1 1 0" name="ankle_3" pos="0.0 0.0 0.0" range="-1.4 -0.8" type="hinge"/>
            <geom fromto="0.0 0.0 0.0 -0.4 -0.4 0.0" name="third_ankle_geom" size="0.08" type="capsule"/>
          </body>
        </body>
      </body>

      <body name="right_back_leg" pos="0 0 0">
        <geom fromto="0.0 0.0 0.0 0.2 -0.2 0.0" name="aux_4_geom" size="0.08" type="capsule"/>
        <body name="aux_4" pos="0.2 -0.2 0">
          <joint axis="0 0 1" name="hip_4" pos="0.0 0.0 0.0" range="-0.7 0.7" type="hinge"/>
          <geom fromto="0.0 0.0 0.0 0.2 -0.2 0.0" name="rightback_leg_geom" size="0.08" type="capsule"/>
          <body pos="0.2 -0.2 0">
            <joint axis="1 1 0" name="ankle_4" pos="0.0 0.0 0.0" range="0.8 1.4" type="hinge"/>
            <geom fromto="0.0 0.0 0.0 0.4 -0.4 0.0" name="fourth_ankle_geom" size="0.08" type="capsule"/>
          </body>
        </body>
      </body>

      <body name="left_feeler" pos="0 0 0">
        <joint axis="0 0 1" name="lf1" pos="0.0 0.0 0.0" range="0.08 0.3" type="hinge"/>
        <geom fromto="0.2 0.0 0.0 0.6 0.0 0.0" name="lf1_geom" size="0.01" density="1" type="capsule" rgba="0 1 1 1"/>
        <body pos="0.6 0.0 0">
          <joint axis="0 1 0" name="lf2" pos="0.0 0.0 0.0" range="-0.65 0.3" type="hinge"/>
          <geom fromto="0.0 0.0 0.0 0.6 0.0 0.0" name="lf2_geom" size="0.01" density="1" type="capsule" rgba="0 1 1 1"/>
        </body>
      </body>

      <body name="right_feeler" pos="0 0 0">
        <joint axis="0 0 1" name="rf1" pos="0.0 0.0 0.0" range="-0.3 -0.08" type="hinge"/>
        <geom fromto="0.2 0.0 0.0 0.6 0.0 0.0" name="rf1_geom" size="0.01" density="1" type="capsule" rgba="0 1 1 1"/>
        <body pos="0.6 0.0 0">
          <joint axis="0 1 0" name="rf2" pos="0.0 0.0 0.0" range="-0.65 0.3" type="hinge"/>
          <geom fromto="0.0 0.0 0.0 0.6 0.0 0.0" name="rf2_geom" size="0.01" density="1" type="capsule" rgba="0 1 1 1"/>
        </body>
      </body>

    </body>


<!-- DEFINE CUBES AND GOAL HERE -->
    <body> 
        <geom conaffinity='1' condim='3' name='cube0_geom' pos='-5.469909026862458 -5.63228144757461 0.6' size='0.5084570681582141 0.39074458493249786 0.6' rgba='1 1 1 1' mass='70' type='box'/>
     </body> 
    <body> 
        <geom conaffinity='1' condim='3' name='cube1_geom' pos='-4.915787180712427 -3.0751342074218053 0.6' size='0.5916806054074427 0.6269723538952632 0.6' rgba='1 1 1 1' mass='70' type='box'/>
     </body> 
    <body> 
        <geom conaffinity='1' condim='3' name='cube2_geom' pos='-6.94165464216405 1.4966815260617032 0.6' size='0.46994520461579303 0.5397460210747973 0.6' rgba='1 1 1 1' mass='70' type='box'/>
     </body> 
    <body> 
        <geom conaffinity='1' condim='3' name='cube3_geom' pos='-5.44130067604803 2.5690221032466987 0.6' size='0.396859458217873 0.5461596046278663 0.6' rgba='1 1 1 1' mass='70' type='box'/>
     </body> 
    <body> 
        <geom conaffinity='1' condim='3' name='cube4_geom' pos='-4.828206959846077 7.035726627042369 0.6' size='0.5348381596518434 0.45007566974743013 0.6' rgba='1 1 1 1' mass='70' type='box'/>
     </body> 
    <body> 
        <geom conaffinity='1' condim='3' name='cube5_geom' pos='-1.9509553474452868 -7.034788806799112 0.6' size='0.41585566415804 0.5852756359073297 0.6' rgba='1 1 1 1' mass='70' type='box'/>
     </body> 
    <body> 
        <geom conaffinity='1' condim='3' name='cube6_geom' pos='-3.3249553129681555 -3.7682984916119424 0.6' size='0.44831395350963676 0.31573105090089626 0.6' rgba='1 1 1 1' mass='70' type='box'/>
     </body> 
    <body> 
        <geom conaffinity='1' condim='3' name='cube7_geom' pos='-1.572782677840829 -0.56186997426428 0.6' size='0.5801997179509739 0.3100459222521345 0.6' rgba='1 1 1 1' mass='70' type='box'/>
     </body> 
    <body> 
        <geom conaffinity='1' condim='3' name='cube8_geom' pos='-2.8026462657535594 2.565653711800209 0.6' size='0.517851509300005 0.526500276116308 0.6' rgba='1 1 1 1' mass='70' type='box'/>
     </body> 
    <body> 
        <geom conaffinity='1' condim='3' name='cube9_geom' pos='-2.1706898610505343 6.431968466795861 0.6' size='0.5194577526417188 0.33869536336238193 0.6' rgba='1 1 1 1' mass='70' type='box'/>
     </body> 
    <body> 
        <geom conaffinity='1' condim='3' name='cube10_geom' pos='-0.4704910159648086 -7.296956012746233 0.6' size='0.6156276341530065 0.31359783906419647 0.6' rgba='1 1 1 1' mass='70' type='box'/>
     </body> 
    <body> 
        <geom conaffinity='1' condim='3' name='cube11_geom' pos='-1.4094238331863171 -4.036896899917631 0.6' size='0.4142667919679942 0.5588334302402964 0.6' rgba='1 1 1 1' mass='70' type='box'/>
     </body> 
    <body> 
        <geom conaffinity='1' condim='3' name='cube12_geom' pos='-0.4612349678984766 2.8613652291145346 0.6' size='0.5391247297842393 0.41500557159696555 0.6' rgba='1 1 1 1' mass='70' type='box'/>
     </body> 
    <body> 
        <geom conaffinity='1' condim='3' name='cube13_geom' pos='-0.5157779337981974 6.337948642745925 0.6' size='0.49241368446940703 0.3777295830195979 0.6' rgba='1 1 1 1' mass='70' type='box'/>
     </body> 
    <body> 
        <geom conaffinity='1' condim='3' name='cube14_geom' pos='2.1879557055442573 -6.424916925792457 0.6' size='0.4084220583025835 0.34495707803621933 0.6' rgba='1 1 1 1' mass='70' type='box'/>
     </body> 
    <body> 
        <geom conaffinity='1' condim='3' name='cube15_geom' pos='4.026937838754609 -3.586259517596281 0.6' size='0.3223702090111914 0.398826550066097 0.6' rgba='1 1 1 1' mass='70' type='box'/>
     </body> 
    <body> 
        <geom conaffinity='1' condim='3' name='cube16_geom' pos='3.9974491800697436 -0.4034240683756152 0.6' size='0.5790617550409382 0.5620464754104697 0.6' rgba='1 1 1 1' mass='70' type='box'/>
     </body> 
    <body> 
        <geom conaffinity='1' condim='3' name='cube17_geom' pos='2.949976318750444 2.1015833456243533 0.6' size='0.6327183497445927 0.41087080897343276 0.6' rgba='1 1 1 1' mass='70' type='box'/>
     </body> 
    <body> 
        <geom conaffinity='1' condim='3' name='cube18_geom' pos='2.46925083337977 6.4398246839604205 0.6' size='0.5801728785555875 0.37922398538721286 0.6' rgba='1 1 1 1' mass='70' type='box'/>
     </body> 
    <body> 
        <geom conaffinity='1' condim='3' name='cube19_geom' pos='7.097642369092684 -6.196872862448214 0.6' size='0.6067167933628059 0.37847159798279784 0.6' rgba='1 1 1 1' mass='70' type='box'/>
     </body> 
    <body> 
        <geom conaffinity='1' condim='3' name='cube20_geom' pos='5.395557331438933 -2.8283427923042 0.6' size='0.5332749788683017 0.5699440641320024 0.6' rgba='1 1 1 1' mass='70' type='box'/>
     </body> 
    <body> 
        <geom conaffinity='1' condim='3' name='cube21_geom' pos='5.48334118055043 0.19335887588303557 0.6' size='0.46065462452773176 0.3690131706077559 0.6' rgba='1 1 1 1' mass='70' type='box'/>
     </body> 
    <body> 
        <geom conaffinity='1' condim='3' name='cube22_geom' pos='6.0718685130997425 1.5638605507983816 0.6' size='0.3028137335257041 0.35874739955460433 0.6' rgba='1 1 1 1' mass='70' type='box'/>
     </body> 
    <body> 
        <geom conaffinity='1' condim='3' name='cube23_geom' pos='6.007362797347708 5.2936019011083735 0.6' size='0.595677969608027 0.5769283162550971 0.6' rgba='1 1 1 1' mass='70' type='box'/>
     </body> 
    <body> 
        <geom conaffinity='1' condim='3' name='goal_geom' pos='2.8411388139154017 -1.7019124013232059 0.6' size='0.3' rgba='1 0 0 1' mass='1' type='sphere'/>
     </body> 



  </worldbody>

  <actuator>
    <position joint="hip_4" kp="20"/>
    <position joint="ankle_4" kp="20"/>
    <position joint="hip_1" kp="20"/>
    <position joint="ankle_1" kp="20"/>
    <position joint="hip_2" kp="20"/>
    <position joint="ankle_2" kp="20"/>
    <position joint="hip_3" kp="20"/>
    <position joint="ankle_3" kp="20"/>
    <motor ctrllimited="true" ctrlrange="-1.0 1.0" joint="lf1" gear="20"/>
    <motor ctrllimited="true" ctrlrange="-1.0 1.0" joint="lf2" gear="20"/>
    <motor ctrllimited="true" ctrlrange="-1.0 1.0" joint="rf1" gear="20"/>
    <motor ctrllimited="true" ctrlrange="-1.0 1.0" joint="rf2" gear="20"/>
  </actuator>
</mujoco>
