<mujoco model="ant">
  <compiler angle="radian" coordinate="local" inertiafromgeom="true"/>
  <option integrator="RK4" timestep="0.01"/>
    <size nconmax="500"/>
  <custom>
    <numeric data="0.0 0.0 0.55 1.0 0.0 0.0 0.0 0.0 1.0 0.0 -1.0 0.0 -1.0 0.0 1.0" name="init_qpos"/>
  </custom>
  <default>
    <joint armature="1" damping="1" limited="true"/>
    <geom conaffinity="0" condim="3" density="5.0" friction="1 0.5 0.5" margin="0.01" rgba="0.8 0.6 0.4 1"/>
  </default>
  <asset>
    <texture builtin="gradient" height="100" rgb1="1 1 1" rgb2="0 0 0" type="skybox" width="100"/>
    <texture builtin="flat" height="1278" mark="cross" markrgb="1 1 1" name="texgeom" random="0.01" rgb1="0.8 0.6 0.4" rgb2="0.8 0.6 0.4" type="cube" width="127"/>
    <texture builtin="checker" height="100" name="texplane" rgb1="0 0 0" rgb2="0.8 0.8 0.8" type="2d" width="100"/>
    <material name="MatPlane" reflectance="0.2" shininess="1" specular="1" texrepeat="0 0" texture="texplane"/>
    <material name="geom" texture="texgeom" texuniform="true"/>
  </asset>

  <worldbody>
    <light cutoff="100" diffuse="1 1 1" dir="-0 0 -1.3" directional="true" exponent="1" pos="0 0 1.3" specular=".1 .1 .1"/>
    <geom conaffinity="1" condim="3" material="MatPlane" name="floor" pos="0 0 0" rgba="0.8 0.9 0.8 1" size="10 10 1" type="plane"/>

    <body name="torso" pos="0 0 0.75">
      <camera name="track" mode="trackcom" pos="0 -3 0.3" xyaxes="1 0 0 0 0 1"/>
      <geom name="torso_geom" pos="0 0 0" size="0.25" mass="0.1" type="sphere"/>
      <joint armature="0" damping="0" limited="false" margin="0.01" name="root" pos="0 0 0" type="free"/>

      <body name="front_left_leg" pos="0 0 0">
        <geom fromto="0.0 0.0 0.0 0.2 0.2 0.0" name="aux_1_geom" size="0.08" type="capsule"/>
        <body name="aux_1" pos="0.2 0.2 0">
          <joint axis="0 0 1" name="hip_1" pos="0.0 0.0 0.0" range="-0.7 0.7" type="hinge"/>
          <geom fromto="0.0 0.0 0.0 0.2 0.2 0.0" name="left_leg_geom" size="0.08" type="capsule"/>
          <body pos="0.2 0.2 0">
            <joint axis="-1 1 0" name="ankle_1" pos="0.0 0.0 0.0" range="0.8 1.4" type="hinge"/>
            <geom fromto="0.0 0.0 0.0 0.4 0.4 0.0" name="left_ankle_geom" size="0.08" type="capsule"/>
          </body>
        </body>
      </body>

      <body name="front_right_leg" pos="0 0 0">
        <geom fromto="0.0 0.0 0.0 -0.2 0.2 0.0" name="aux_2_geom" size="0.08" type="capsule"/>
        <body name="aux_2" pos="-0.2 0.2 0">
          <joint axis="0 0 1" name="hip_2" pos="0.0 0.0 0.0" range="-0.7 0.7" type="hinge"/>
          <geom fromto="0.0 0.0 0.0 -0.2 0.2 0.0" name="right_leg_geom" size="0.08" type="capsule"/>
          <body pos="-0.2 0.2 0">
            <joint axis="1 1 0" name="ankle_2" pos="0.0 0.0 0.0" range="-1.4 -0.8" type="hinge"/>
            <geom fromto="0.0 0.0 0.0 -0.4 0.4 0.0" name="right_ankle_geom" size="0.08" type="capsule"/>
          </body>
        </body>
      </body>

      <body name="back_leg" pos="0 0 0">
        <geom fromto="0.0 0.0 0.0 -0.2 -0.2 0.0" name="aux_3_geom" size="0.08" type="capsule"/>
        <body name="aux_3" pos="-0.2 -0.2 0">
          <joint axis="0 0 1" name="hip_3" pos="0.0 0.0 0.0" range="-0.7 0.7" type="hinge"/>
          <geom fromto="0.0 0.0 0.0 -0.2 -0.2 0.0" name="back_leg_geom" size="0.08" type="capsule"/>
          <body pos="-0.2 -0.2 0">
            <joint axis="-1 1 0" name="ankle_3" pos="0.0 0.0 0.0" range="-1.4 -0.8" type="hinge"/>
            <geom fromto="0.0 0.0 0.0 -0.4 -0.4 0.0" name="third_ankle_geom" size="0.08" type="capsule"/>
          </body>
        </body>
      </body>

      <body name="right_back_leg" pos="0 0 0">
        <geom fromto="0.0 0.0 0.0 0.2 -0.2 0.0" name="aux_4_geom" size="0.08" type="capsule"/>
        <body name="aux_4" pos="0.2 -0.2 0">
          <joint axis="0 0 1" name="hip_4" pos="0.0 0.0 0.0" range="-0.7 0.7" type="hinge"/>
          <geom fromto="0.0 0.0 0.0 0.2 -0.2 0.0" name="rightback_leg_geom" size="0.08" type="capsule"/>
          <body pos="0.2 -0.2 0">
            <joint axis="1 1 0" name="ankle_4" pos="0.0 0.0 0.0" range="0.8 1.4" type="hinge"/>
            <geom fromto="0.0 0.0 0.0 0.4 -0.4 0.0" name="fourth_ankle_geom" size="0.08" type="capsule"/>
          </body>
        </body>
      </body>

      <body name="left_feeler" pos="0 0 0">
        <joint axis="0 0 1" name="lf1" pos="0.0 0.0 0.0" range="0.08 0.3" type="hinge"/>
        <geom fromto="0.2 0.0 0.0 0.6 0.0 0.0" name="lf1_geom" size="0.01" density="1" type="capsule" rgba="0 1 1 1"/>
        <body pos="0.6 0.0 0">
          <joint axis="0 1 0" name="lf2" pos="0.0 0.0 0.0" range="-0.65 0.3" type="hinge"/>
          <geom fromto="0.0 0.0 0.0 0.6 0.0 0.0" name="lf2_geom" size="0.01" density="1" type="capsule" rgba="0 1 1 1"/>
        </body>
      </body>

      <body name="right_feeler" pos="0 0 0">
        <joint axis="0 0 1" name="rf1" pos="0.0 0.0 0.0" range="-0.3 -0.08" type="hinge"/>
        <geom fromto="0.2 0.0 0.0 0.6 0.0 0.0" name="rf1_geom" size="0.01" density="1" type="capsule" rgba="0 1 1 1"/>
        <body pos="0.6 0.0 0">
          <joint axis="0 1 0" name="rf2" pos="0.0 0.0 0.0" range="-0.65 0.3" type="hinge"/>
          <geom fromto="0.0 0.0 0.0 0.6 0.0 0.0" name="rf2_geom" size="0.01" density="1" type="capsule" rgba="0 1 1 1"/>
        </body>
      </body>

    </body>


<!-- DEFINE CUBES AND GOAL HERE -->
    <body> 
        <geom conaffinity='1' condim='3' name='cube0_geom' pos='-7.3781304196136555 -6.366649550285653 0.6' size='0.3891573920577454 0.37464859868899364 0.6' rgba='1 1 1 1' mass='70' type='box'/>
     </body> 
    <body> 
        <geom conaffinity='1' condim='3' name='cube1_geom' pos='-6.8643499451109244 -2.8700362341558834 0.6' size='0.32708211790295305 0.40997366242124333 0.6' rgba='1 1 1 1' mass='70' type='box'/>
     </body> 
    <body> 
        <geom conaffinity='1' condim='3' name='cube2_geom' pos='-6.398596094191582 0.18210950052421726 0.6' size='0.5673476828544879 0.5217458674952997 0.6' rgba='1 1 1 1' mass='70' type='box'/>
     </body> 
    <body> 
        <geom conaffinity='1' condim='3' name='cube3_geom' pos='-6.407472681550438 4.016363741990075 0.6' size='0.518703179884021 0.30857042282583985 0.6' rgba='1 1 1 1' mass='70' type='box'/>
     </body> 
    <body> 
        <geom conaffinity='1' condim='3' name='cube4_geom' pos='-5.339668969782007 6.756438241715916 0.6' size='0.5998497046540402 0.45968392743888264 0.6' rgba='1 1 1 1' mass='70' type='box'/>
     </body> 
    <body> 
        <geom conaffinity='1' condim='3' name='cube5_geom' pos='-1.8409230536766303 -5.736001415066635 0.6' size='0.4312122833397083 0.5559598436694783 0.6' rgba='1 1 1 1' mass='70' type='box'/>
     </body> 
    <body> 
        <geom conaffinity='1' condim='3' name='cube6_geom' pos='-3.9741314847915428 -4.474850641258908 0.6' size='0.4800105127465704 0.5939234514348436 0.6' rgba='1 1 1 1' mass='70' type='box'/>
     </body> 
    <body> 
        <geom conaffinity='1' condim='3' name='cube7_geom' pos='-4.315500398510512 -1.2025622146457833 0.6' size='0.42327736272824723 0.3131533823972389 0.6' rgba='1 1 1 1' mass='70' type='box'/>
     </body> 
    <body> 
        <geom conaffinity='1' condim='3' name='cube8_geom' pos='-1.7186537443567844 2.515895603261808 0.6' size='0.33951231724659203 0.6051097012820977 0.6' rgba='1 1 1 1' mass='70' type='box'/>
     </body> 
    <body> 
        <geom conaffinity='1' condim='3' name='cube9_geom' pos='-2.63886337247882 6.256868566507793 0.6' size='0.3156482719697814 0.3952153851201109 0.6' rgba='1 1 1 1' mass='70' type='box'/>
     </body> 
    <body> 
        <geom conaffinity='1' condim='3' name='cube10_geom' pos='0.002807363074865954 -6.431189360139336 0.6' size='0.5179080508578479 0.36982554398221096 0.6' rgba='1 1 1 1' mass='70' type='box'/>
     </body> 
    <body> 
        <geom conaffinity='1' condim='3' name='cube11_geom' pos='1.2475680753973593 -1.615453603249283 0.6' size='0.6211255654540796 0.43858411995748414 0.6' rgba='1 1 1 1' mass='70' type='box'/>
     </body> 
    <body> 
        <geom conaffinity='1' condim='3' name='cube12_geom' pos='-0.812067692207321 -1.4197255435532252 0.6' size='0.5242878590643563 0.6223706143280614 0.6' rgba='1 1 1 1' mass='70' type='box'/>
     </body> 
    <body> 
        <geom conaffinity='1' condim='3' name='cube13_geom' pos='1.4234365664779691 1.838279078500313 0.6' size='0.5296997721107126 0.475592222911134 0.6' rgba='1 1 1 1' mass='70' type='box'/>
     </body> 
    <body> 
        <geom conaffinity='1' condim='3' name='cube14_geom' pos='-0.1142069633804299 6.3980835733184325 0.6' size='0.3483297667362344 0.5139767399487276 0.6' rgba='1 1 1 1' mass='70' type='box'/>
     </body> 
    <body> 
        <geom conaffinity='1' condim='3' name='cube15_geom' pos='3.6127193736237935 -5.588741527191663 0.6' size='0.49642044574366034 0.5438629530739019 0.6' rgba='1 1 1 1' mass='70' type='box'/>
     </body> 
    <body> 
        <geom conaffinity='1' condim='3' name='cube16_geom' pos='3.258719348814422 -3.6263245724342865 0.6' size='0.3393095593013401 0.40247823170219366 0.6' rgba='1 1 1 1' mass='70' type='box'/>
     </body> 
    <body> 
        <geom conaffinity='1' condim='3' name='cube17_geom' pos='3.313403343341969 -1.302043841597018 0.6' size='0.6183580342021733 0.5371115267704247 0.6' rgba='1 1 1 1' mass='70' type='box'/>
     </body> 
    <body> 
        <geom conaffinity='1' condim='3' name='cube18_geom' pos='3.0736523769389805 3.0180302825601393 0.6' size='0.5403353450228622 0.43268951818501633 0.6' rgba='1 1 1 1' mass='70' type='box'/>
     </body> 
    <body> 
        <geom conaffinity='1' condim='3' name='cube19_geom' pos='3.75908306176858 6.048292969428977 0.6' size='0.39743404875227195 0.30790697195933764 0.6' rgba='1 1 1 1' mass='70' type='box'/>
     </body> 
    <body> 
        <geom conaffinity='1' condim='3' name='cube20_geom' pos='6.560110386671184 -7.160651119877421 0.6' size='0.41567876519197866 0.5103647229323928 0.6' rgba='1 1 1 1' mass='70' type='box'/>
     </body> 
    <body> 
        <geom conaffinity='1' condim='3' name='cube21_geom' pos='6.9486949086385295 -2.9321334879796086 0.6' size='0.3774295695156912 0.5715092076575023 0.6' rgba='1 1 1 1' mass='70' type='box'/>
     </body> 
    <body> 
        <geom conaffinity='1' condim='3' name='cube22_geom' pos='5.257064603087257 0.002685479537600788 0.6' size='0.5216691977366075 0.42533594662159013 0.6' rgba='1 1 1 1' mass='70' type='box'/>
     </body> 
    <body> 
        <geom conaffinity='1' condim='3' name='cube23_geom' pos='5.567029619918782 2.0661196586631108 0.6' size='0.41891790179034855 0.3753408387582335 0.6' rgba='1 1 1 1' mass='70' type='box'/>
     </body> 
    <body> 
        <geom conaffinity='1' condim='3' name='cube24_geom' pos='7.438452148376069 6.225042745721874 0.6' size='0.5242329839264324 0.4783646681298211 0.6' rgba='1 1 1 1' mass='70' type='box'/>
     </body> 
    <body> 
        <geom conaffinity='1' condim='3' name='goal_geom' pos='5.948200927248772 5.043549039776627 0.6' size='0.3' rgba='1 0 0 1' mass='1' type='sphere'/>
     </body> 



  </worldbody>

  <actuator>
    <position joint="hip_4" kp="20"/>
    <position joint="ankle_4" kp="20"/>
    <position joint="hip_1" kp="20"/>
    <position joint="ankle_1" kp="20"/>
    <position joint="hip_2" kp="20"/>
    <position joint="ankle_2" kp="20"/>
    <position joint="hip_3" kp="20"/>
    <position joint="ankle_3" kp="20"/>
    <motor ctrllimited="true" ctrlrange="-1.0 1.0" joint="lf1" gear="20"/>
    <motor ctrllimited="true" ctrlrange="-1.0 1.0" joint="lf2" gear="20"/>
    <motor ctrllimited="true" ctrlrange="-1.0 1.0" joint="rf1" gear="20"/>
    <motor ctrllimited="true" ctrlrange="-1.0 1.0" joint="rf2" gear="20"/>
  </actuator>
</mujoco>
