<mujoco model="ant">
  <compiler angle="radian" coordinate="local" inertiafromgeom="true"/>
  <option integrator="RK4" timestep="0.01"/>
    <size nconmax="500"/>
  <custom>
    <numeric data="0.0 0.0 0.55 1.0 0.0 0.0 0.0 0.0 1.0 0.0 -1.0 0.0 -1.0 0.0 1.0" name="init_qpos"/>
  </custom>
  <default>
    <joint armature="1" damping="1" limited="true"/>
    <geom conaffinity="0" condim="3" density="5.0" friction="1 0.5 0.5" margin="0.01" rgba="0.8 0.6 0.4 1"/>
  </default>
  <asset>
    <texture builtin="gradient" height="100" rgb1="1 1 1" rgb2="0 0 0" type="skybox" width="100"/>
    <texture builtin="flat" height="1278" mark="cross" markrgb="1 1 1" name="texgeom" random="0.01" rgb1="0.8 0.6 0.4" rgb2="0.8 0.6 0.4" type="cube" width="127"/>
    <texture builtin="checker" height="100" name="texplane" rgb1="0 0 0" rgb2="0.8 0.8 0.8" type="2d" width="100"/>
    <material name="MatPlane" reflectance="0.2" shininess="1" specular="1" texrepeat="0 0" texture="texplane"/>
    <material name="geom" texture="texgeom" texuniform="true"/>
  </asset>

  <worldbody>
    <light cutoff="100" diffuse="1 1 1" dir="-0 0 -1.3" directional="true" exponent="1" pos="0 0 1.3" specular=".1 .1 .1"/>
    <geom conaffinity="1" condim="3" material="MatPlane" name="floor" pos="0 0 0" rgba="0.8 0.9 0.8 1" size="10 10 1" type="plane"/>

    <body name="torso" pos="0 0 0.75">
      <camera name="track" mode="trackcom" pos="0 -3 0.3" xyaxes="1 0 0 0 0 1"/>
      <geom name="torso_geom" pos="0 0 0" size="0.25" mass="0.1" type="sphere"/>
      <joint armature="0" damping="0" limited="false" margin="0.01" name="root" pos="0 0 0" type="free"/>

      <body name="front_left_leg" pos="0 0 0">
        <geom fromto="0.0 0.0 0.0 0.2 0.2 0.0" name="aux_1_geom" size="0.08" type="capsule"/>
        <body name="aux_1" pos="0.2 0.2 0">
          <joint axis="0 0 1" name="hip_1" pos="0.0 0.0 0.0" range="-0.7 0.7" type="hinge"/>
          <geom fromto="0.0 0.0 0.0 0.2 0.2 0.0" name="left_leg_geom" size="0.08" type="capsule"/>
          <body pos="0.2 0.2 0">
            <joint axis="-1 1 0" name="ankle_1" pos="0.0 0.0 0.0" range="0.8 1.4" type="hinge"/>
            <geom fromto="0.0 0.0 0.0 0.4 0.4 0.0" name="left_ankle_geom" size="0.08" type="capsule"/>
          </body>
        </body>
      </body>

      <body name="front_right_leg" pos="0 0 0">
        <geom fromto="0.0 0.0 0.0 -0.2 0.2 0.0" name="aux_2_geom" size="0.08" type="capsule"/>
        <body name="aux_2" pos="-0.2 0.2 0">
          <joint axis="0 0 1" name="hip_2" pos="0.0 0.0 0.0" range="-0.7 0.7" type="hinge"/>
          <geom fromto="0.0 0.0 0.0 -0.2 0.2 0.0" name="right_leg_geom" size="0.08" type="capsule"/>
          <body pos="-0.2 0.2 0">
            <joint axis="1 1 0" name="ankle_2" pos="0.0 0.0 0.0" range="-1.4 -0.8" type="hinge"/>
            <geom fromto="0.0 0.0 0.0 -0.4 0.4 0.0" name="right_ankle_geom" size="0.08" type="capsule"/>
          </body>
        </body>
      </body>

      <body name="back_leg" pos="0 0 0">
        <geom fromto="0.0 0.0 0.0 -0.2 -0.2 0.0" name="aux_3_geom" size="0.08" type="capsule"/>
        <body name="aux_3" pos="-0.2 -0.2 0">
          <joint axis="0 0 1" name="hip_3" pos="0.0 0.0 0.0" range="-0.7 0.7" type="hinge"/>
          <geom fromto="0.0 0.0 0.0 -0.2 -0.2 0.0" name="back_leg_geom" size="0.08" type="capsule"/>
          <body pos="-0.2 -0.2 0">
            <joint axis="-1 1 0" name="ankle_3" pos="0.0 0.0 0.0" range="-1.4 -0.8" type="hinge"/>
            <geom fromto="0.0 0.0 0.0 -0.4 -0.4 0.0" name="third_ankle_geom" size="0.08" type="capsule"/>
          </body>
        </body>
      </body>

      <body name="right_back_leg" pos="0 0 0">
        <geom fromto="0.0 0.0 0.0 0.2 -0.2 0.0" name="aux_4_geom" size="0.08" type="capsule"/>
        <body name="aux_4" pos="0.2 -0.2 0">
          <joint axis="0 0 1" name="hip_4" pos="0.0 0.0 0.0" range="-0.7 0.7" type="hinge"/>
          <geom fromto="0.0 0.0 0.0 0.2 -0.2 0.0" name="rightback_leg_geom" size="0.08" type="capsule"/>
          <body pos="0.2 -0.2 0">
            <joint axis="1 1 0" name="ankle_4" pos="0.0 0.0 0.0" range="0.8 1.4" type="hinge"/>
            <geom fromto="0.0 0.0 0.0 0.4 -0.4 0.0" name="fourth_ankle_geom" size="0.08" type="capsule"/>
          </body>
        </body>
      </body>

      <body name="left_feeler" pos="0 0 0">
        <joint axis="0 0 1" name="lf1" pos="0.0 0.0 0.0" range="0.08 0.3" type="hinge"/>
        <geom fromto="0.2 0.0 0.0 0.6 0.0 0.0" name="lf1_geom" size="0.01" density="1" type="capsule" rgba="0 1 1 1"/>
        <body pos="0.6 0.0 0">
          <joint axis="0 1 0" name="lf2" pos="0.0 0.0 0.0" range="-0.65 0.3" type="hinge"/>
          <geom fromto="0.0 0.0 0.0 0.6 0.0 0.0" name="lf2_geom" size="0.01" density="1" type="capsule" rgba="0 1 1 1"/>
        </body>
      </body>

      <body name="right_feeler" pos="0 0 0">
        <joint axis="0 0 1" name="rf1" pos="0.0 0.0 0.0" range="-0.3 -0.08" type="hinge"/>
        <geom fromto="0.2 0.0 0.0 0.6 0.0 0.0" name="rf1_geom" size="0.01" density="1" type="capsule" rgba="0 1 1 1"/>
        <body pos="0.6 0.0 0">
          <joint axis="0 1 0" name="rf2" pos="0.0 0.0 0.0" range="-0.65 0.3" type="hinge"/>
          <geom fromto="0.0 0.0 0.0 0.6 0.0 0.0" name="rf2_geom" size="0.01" density="1" type="capsule" rgba="0 1 1 1"/>
        </body>
      </body>

    </body>


<!-- DEFINE CUBES AND GOAL HERE -->
    <body> 
        <geom conaffinity='1' condim='3' name='cube0_geom' pos='-7.3093334237085985 -6.6775535658754865 0.6' size='0.3544566385826743 0.631199049136008 0.6' rgba='1 1 1 1' mass='70' type='box'/>
     </body> 
    <body> 
        <geom conaffinity='1' condim='3' name='cube1_geom' pos='-5.489327407507787 -4.204769270209573 0.6' size='0.5791799862707386 0.3559330348162475 0.6' rgba='1 1 1 1' mass='70' type='box'/>
     </body> 
    <body> 
        <geom conaffinity='1' condim='3' name='cube2_geom' pos='-4.893473733509585 -0.1930277417415187 0.6' size='0.3281720999104406 0.38153281762849106 0.6' rgba='1 1 1 1' mass='70' type='box'/>
     </body> 
    <body> 
        <geom conaffinity='1' condim='3' name='cube3_geom' pos='-6.907688952046946 2.1724849146075025 0.6' size='0.44237774930236345 0.3609469945332006 0.6' rgba='1 1 1 1' mass='70' type='box'/>
     </body> 
    <body> 
        <geom conaffinity='1' condim='3' name='cube4_geom' pos='-7.182731787027503 7.40160538628292 0.6' size='0.5873369821627243 0.6010701701169587 0.6' rgba='1 1 1 1' mass='70' type='box'/>
     </body> 
    <body> 
        <geom conaffinity='1' condim='3' name='cube5_geom' pos='-3.1151112220562722 -5.853241036598452 0.6' size='0.5899295508378424 0.5907008179100016 0.6' rgba='1 1 1 1' mass='70' type='box'/>
     </body> 
    <body> 
        <geom conaffinity='1' condim='3' name='cube6_geom' pos='-4.081705979460261 -2.1166702686810277 0.6' size='0.34765415828589896 0.4679765899159387 0.6' rgba='1 1 1 1' mass='70' type='box'/>
     </body> 
    <body> 
        <geom conaffinity='1' condim='3' name='cube7_geom' pos='-3.0547111758708647 0.02302240912627651 0.6' size='0.30105220089077905 0.395098711106376 0.6' rgba='1 1 1 1' mass='70' type='box'/>
     </body> 
    <body> 
        <geom conaffinity='1' condim='3' name='cube8_geom' pos='-4.418956136604706 3.8226200620665116 0.6' size='0.4799311092979339 0.47724746805843 0.6' rgba='1 1 1 1' mass='70' type='box'/>
     </body> 
    <body> 
        <geom conaffinity='1' condim='3' name='cube9_geom' pos='-2.278908929686985 5.395013544577823 0.6' size='0.38796060961118267 0.4093752455652512 0.6' rgba='1 1 1 1' mass='70' type='box'/>
     </body> 
    <body> 
        <geom conaffinity='1' condim='3' name='cube10_geom' pos='1.0379282488450272 -6.269048807073318 0.6' size='0.5357753605700379 0.3917962975673625 0.6' rgba='1 1 1 1' mass='70' type='box'/>
     </body> 
    <body> 
        <geom conaffinity='1' condim='3' name='cube11_geom' pos='0.9564395109294104 -4.272741510667154 0.6' size='0.44470112303098885 0.5496287138798905 0.6' rgba='1 1 1 1' mass='70' type='box'/>
     </body> 
    <body> 
        <geom conaffinity='1' condim='3' name='cube12_geom' pos='-1.2367203379468386 -1.1307226226023936 0.6' size='0.5491175187770758 0.4117232594765508 0.6' rgba='1 1 1 1' mass='70' type='box'/>
     </body> 
    <body> 
        <geom conaffinity='1' condim='3' name='cube13_geom' pos='0.7985946310987906 1.6046080652879726 0.6' size='0.3950879494168677 0.6254266573015979 0.6' rgba='1 1 1 1' mass='70' type='box'/>
     </body> 
    <body> 
        <geom conaffinity='1' condim='3' name='cube14_geom' pos='-1.195013197764752 6.9148785896252605 0.6' size='0.45286086604465986 0.57476304156155 0.6' rgba='1 1 1 1' mass='70' type='box'/>
     </body> 
    <body> 
        <geom conaffinity='1' condim='3' name='cube15_geom' pos='3.9294931704366878 -5.076687163494877 0.6' size='0.6171464746130384 0.3522678838260727 0.6' rgba='1 1 1 1' mass='70' type='box'/>
     </body> 
    <body> 
        <geom conaffinity='1' condim='3' name='cube16_geom' pos='4.184987060122648 -2.5796485476629956 0.6' size='0.6132571093125683 0.4150861469325423 0.6' rgba='1 1 1 1' mass='70' type='box'/>
     </body> 
    <body> 
        <geom conaffinity='1' condim='3' name='cube17_geom' pos='2.2008648862980196 1.4633407113783603 0.6' size='0.3593556582713263 0.31053740994623746 0.6' rgba='1 1 1 1' mass='70' type='box'/>
     </body> 
    <body> 
        <geom conaffinity='1' condim='3' name='cube18_geom' pos='4.2257791311251625 1.829946028537318 0.6' size='0.4695254025650392 0.4452795778405085 0.6' rgba='1 1 1 1' mass='70' type='box'/>
     </body> 
    <body> 
        <geom conaffinity='1' condim='3' name='cube19_geom' pos='7.184353989622036 -6.7301358692575155 0.6' size='0.536686235653391 0.37494790304420084 0.6' rgba='1 1 1 1' mass='70' type='box'/>
     </body> 
    <body> 
        <geom conaffinity='1' condim='3' name='cube20_geom' pos='4.588536788464287 -1.7499477736800548 0.6' size='0.3108371154135202 0.34565272326571994 0.6' rgba='1 1 1 1' mass='70' type='box'/>
     </body> 
    <body> 
        <geom conaffinity='1' condim='3' name='cube21_geom' pos='6.602161785102814 1.2219037789547826 0.6' size='0.42332046087607245 0.4360424228677643 0.6' rgba='1 1 1 1' mass='70' type='box'/>
     </body> 
    <body> 
        <geom conaffinity='1' condim='3' name='cube22_geom' pos='4.575926491931542 1.9745415274460831 0.6' size='0.573949568968255 0.5322630285906582 0.6' rgba='1 1 1 1' mass='70' type='box'/>
     </body> 
    <body> 
        <geom conaffinity='1' condim='3' name='cube23_geom' pos='5.990786710758506 6.609182298466786 0.6' size='0.5968988111170607 0.368446783982705 0.6' rgba='1 1 1 1' mass='70' type='box'/>
     </body> 
    <body> 
        <geom conaffinity='1' condim='3' name='goal_geom' pos='3.548548652034048 5.377540712502806 0.6' size='0.3' rgba='1 0 0 1' mass='1' type='sphere'/>
     </body> 



  </worldbody>

  <actuator>
    <position joint="hip_4" kp="20"/>
    <position joint="ankle_4" kp="20"/>
    <position joint="hip_1" kp="20"/>
    <position joint="ankle_1" kp="20"/>
    <position joint="hip_2" kp="20"/>
    <position joint="ankle_2" kp="20"/>
    <position joint="hip_3" kp="20"/>
    <position joint="ankle_3" kp="20"/>
    <motor ctrllimited="true" ctrlrange="-1.0 1.0" joint="lf1" gear="20"/>
    <motor ctrllimited="true" ctrlrange="-1.0 1.0" joint="lf2" gear="20"/>
    <motor ctrllimited="true" ctrlrange="-1.0 1.0" joint="rf1" gear="20"/>
    <motor ctrllimited="true" ctrlrange="-1.0 1.0" joint="rf2" gear="20"/>
  </actuator>
</mujoco>
