<mujoco model="ant">
  <compiler angle="radian" coordinate="local" inertiafromgeom="true"/>
  <option integrator="RK4" timestep="0.01"/>
    <size nconmax="500"/>
  <custom>
    <numeric data="0.0 0.0 0.55 1.0 0.0 0.0 0.0 0.0 1.0 0.0 -1.0 0.0 -1.0 0.0 1.0" name="init_qpos"/>
  </custom>
  <default>
    <joint armature="1" damping="1" limited="true"/>
    <geom conaffinity="0" condim="3" density="5.0" friction="1 0.5 0.5" margin="0.01" rgba="0.8 0.6 0.4 1"/>
  </default>
  <asset>
    <texture builtin="gradient" height="100" rgb1="1 1 1" rgb2="0 0 0" type="skybox" width="100"/>
    <texture builtin="flat" height="1278" mark="cross" markrgb="1 1 1" name="texgeom" random="0.01" rgb1="0.8 0.6 0.4" rgb2="0.8 0.6 0.4" type="cube" width="127"/>
    <texture builtin="checker" height="100" name="texplane" rgb1="0 0 0" rgb2="0.8 0.8 0.8" type="2d" width="100"/>
    <material name="MatPlane" reflectance="0.2" shininess="1" specular="1" texrepeat="0 0" texture="texplane"/>
    <material name="geom" texture="texgeom" texuniform="true"/>
  </asset>

  <worldbody>
    <light cutoff="100" diffuse="1 1 1" dir="-0 0 -1.3" directional="true" exponent="1" pos="0 0 1.3" specular=".1 .1 .1"/>
    <geom conaffinity="1" condim="3" material="MatPlane" name="floor" pos="4 0 0" rgba="0.8 0.9 0.8 1" size="6 2.4 1" type="plane"/>

    <body name="torso" pos="0 0 0.75">
      <camera name="track" mode="trackcom" pos="0 -3 0.3" xyaxes="1 0 0 0 0 1"/>
      <geom name="torso_geom" pos="0 0 0" size="0.35 0.25 0.1" mass="0.1" type="box"/>
      <joint armature="0" damping="0" limited="false" margin="0.01" name="root" pos="0 0 0" type="free"/>

       <body name="front_left_leg" pos="0.2 0.2 0">
        <joint axis="0 1 0" name="hip_1" pos="0.0 0.0 0.0" range="0.5 1.5" type="hinge"/>
          <geom fromto="0.0 0.0 0.0 0.2 0.0 0.0" name="coxa_fl_geom" size="0.06" type="capsule"/>
          <body pos="0.2 0.0 0">
            <joint axis="0 1 0" name="knee_1" pos="0.0 0.0 0.0" range="0.5 1.5" type="hinge"/>
            <geom fromto="0.0 0.0 0.0 0.4 0.0 0.0" name="femur_fl_geom" size="0.06" type="capsule"/>
          </body>
      </body>

      <body name="front_right_leg" pos="0.2 -0.2 0">
        <joint axis="0 1 0" name="hip_2" pos="0.0 0.0 0.0" range="0.5 1.5" type="hinge"/>
          <geom fromto="0.0 0.0 0.0 0.2 0.0 0.0" name="coxa_fr_geom" size="0.06" type="capsule"/>
          <body pos="0.2 0.0 0">
            <joint axis="0 1 0" name="knee_2" pos="0.0 0.0 0.0" range="0.5 1.5" type="hinge"/>
            <geom fromto="0.0 0.0 0.0 0.4 0.0 0.0" name="femur_fr_geom" size="0.06" type="capsule"/>
          </body>
      </body>

      <body name="back_left_leg" pos="-0.2 0.2 0">
        <joint axis="0 -1 0" name="hip_3" pos="0.0 0.0 0.0" range="0.5 1.5" type="hinge"/>
          <geom fromto="0.0 0.0 0.0 -0.2 0.0 0.0" name="coxa_rl_geom" size="0.06" type="capsule"/>
          <body pos="-0.2 0.0 0">
            <joint axis="0 -1 0" name="knee_3" pos="0.0 0.0 0.0" range="0.5 1.5" type="hinge"/>
            <geom fromto="0.0 0.0 0.0 -0.4 0.0 0.0" name="femur_rl_geom" size="0.06" type="capsule"/>
          </body>
      </body>

      <body name="back_right_leg" pos="-0.2 -0.2 0">
        <joint axis="0 -1 0" name="hip_4" pos="0.0 0.0 0.0" range="0.5 1.5" type="hinge"/>
          <geom fromto="0.0 0.0 0.0 -0.2 0.0 0.0" name="coxa_rr_geom" size="0.06" type="capsule"/>
          <body pos="-0.2 0.0 0">
            <joint axis="0 -1 0" name="knee_4" pos="0.0 0.0 0.0" range="0.5 1.5" type="hinge"/>
            <geom fromto="0.0 0.0 0.0 -0.4 -0.0 0.0" name="femur_rr_geom" size="0.06" type="capsule"/>
          </body>
      </body>


       <body name="left_feeler" pos="0 0 0">
        <joint axis="0 0 1" name="lf1" pos="0.0 0.0 0.0" range="0.08 0.3" type="hinge"/>
        <geom fromto="0.2 0.0 0.0 0.6 0.0 0.0" name="lf1_geom" size="0.01" density="1" type="capsule" rgba="0 1 1 1"/>
        <body pos="0.6 0.0 0">
          <joint axis="0 1 0" name="lf2" pos="0.0 0.0 0.0" range="-0.65 0.3" type="hinge"/>
          <geom fromto="0.0 0.0 0.0 0.6 0.0 0.0" name="lf2_geom" size="0.01" density="1" type="capsule" rgba="0 1 1 1"/>
        </body>
      </body>

      <body name="right_feeler" pos="0 0 0">
        <joint axis="0 0 1" name="rf1" pos="0.0 0.0 0.0" range="-0.3 -0.08" type="hinge"/>
        <geom fromto="0.2 0.0 0.0 0.6 0.0 0.0" name="rf1_geom" size="0.01" density="1" type="capsule" rgba="0 1 1 1"/>
        <body pos="0.6 0.0 0">
          <joint axis="0 1 0" name="rf2" pos="0.0 0.0 0.0" range="-0.65 0.3" type="hinge"/>
          <geom fromto="0.0 0.0 0.0 0.6 0.0 0.0" name="rf2_geom" size="0.01" density="1" type="capsule" rgba="0 1 1 1"/>
        </body>
      </body>

    </body>

    <body>
        <freejoint name="cube_0"/>
        <geom conaffinity="1" condim="3" name="cube0_geom" pos="0 0 0" size="0.4 0.5 0.6" rgba="1 1 1 1" mass="70" type="box"/>
    </body>

    <body>
        <freejoint name="cube_1"/>
        <geom conaffinity="1" condim="3" name="cube1_geom" pos="0 0 0" size="0.4 0.5 0.6" rgba="1 1 1 1" mass="70" type="box"/>
    </body>

    <body>
        <freejoint name="cube_2"/>
        <geom conaffinity="1" condim="3" name="cube2_geom" pos="0 0 0" size="0.4 0.5 0.6" rgba="1 1 1 1" mass="70" type="box"/>
    </body>

    <body>
        <freejoint name="cube_3"/>
        <geom conaffinity="1" condim="3" name="cube3_geom" pos="0 0 0" size="0.4 0.5 0.6" rgba="1 1 1 1" mass="70" type="box"/>
    </body>

    <body>
        <geom conaffinity="1" condim="3" name="wall1_geom" pos="4 2.4 0.6" size="6.0 0.1 0.6" rgba="1 1 1 1" mass="70" type="box"/>
    </body>

    <body>
        <geom conaffinity="1" condim="3" name="wall2_geom" pos="4 -2.4 0.6" size="6.0 0.1 0.6" rgba="1 1 1 1" mass="70" type="box"/>
    </body>

    <body>
        <geom conaffinity="1" condim="3" name="wall3_geom" pos="-2 0 0.6" size=".1 2.5 0.6" rgba="1 1 1 1" mass="70" type="box"/>
    </body>

    <body>
        <geom conaffinity="1" condim="3" name="wall4_geom" pos="10 0 0.6" size=".1 2.5 0.6" rgba="1 1 1 1" mass="70" type="box"/>
    </body>

  </worldbody>

  <actuator>
    <position joint="hip_1" kp="20"/>
    <position joint="knee_1" kp="20"/>
    <position joint="hip_2" kp="20"/>
    <position joint="knee_2" kp="20"/>
    <position joint="hip_3" kp="20"/>
    <position joint="knee_3" kp="20"/>
    <position joint="hip_4" kp="20"/>
    <position joint="knee_4" kp="20"/>
    <motor ctrllimited="true" ctrlrange="-1 1" joint="lf1" gear="20"/>
    <motor ctrllimited="true" ctrlrange="-1 1" joint="lf2" gear="20"/>
    <motor ctrllimited="true" ctrlrange="-1 1" joint="rf1" gear="20"/>
    <motor ctrllimited="true" ctrlrange="-1 1" joint="rf2" gear="20"/>
  </actuator>
</mujoco>
