<mujoco model="quad">
  <compiler angle="radian" coordinate="local" inertiafromgeom="true"/>
  <option integrator="RK4" timestep="0.02"/>
  <size nconmax="1000" njmax="2000"/>

  <default>
    <joint armature="0.5" damping="3" limited="true"/>
    <geom conaffinity="0" condim="3" density="5.0" friction="1.0 0.5 0.5" margin="0.001" rgba="0.2 0.2 0.2 0.8"/>
  </default>

  <asset>
    <texture type="skybox" builtin="gradient" width="100" height="100" rgb1="1 1 1" rgb2="0 0 0" />
    <texture name="texgeom" type="cube" builtin="flat" mark="cross" width="127" height="127" rgb1="0.8 0.6 0.4" rgb2="0.8 0.6 0.4" markrgb="1 1 1" random="0.01" />
    <texture name="texplane" type="2d" width="1" height="1" file="white2.png"/>
    <texture name="texhex" type="2d" width="1" height="1" file="white2.png"/>
    <texture name="texleg" type="2d" width="1" height="1" file="white2.png"/>
    <material name="MatPlane" reflectance="0.0" shininess="1" specular="1" texrepeat="6 6" texture="texplane"/>
    <material name="MatHex" reflectance="0.0" shininess="1" specular="1" texrepeat="0.6 0.6" texture="texhex"/>
    <material name="MatLeg" reflectance="0.0" shininess="1" specular="1" texrepeat="1 1" texture="texleg"/>
    <material name='geom' texture="texgeom" texuniform="true" />
    <hfield name="hill" file="hm.png" size="4.0 2.0 1.0 0.1" />
   </asset>

  <worldbody>
    <light cutoff="100" diffuse="0.7 0.7 0.7" dir="0 0 -1.3" directional="true" exponent="1" pos="0 0 0" specular="0.1 0.1 0.1"/>
    <geom name="floor" conaffinity="1" condim="3" material="MatPlane" pos="3.6 0 -.1" rgba="0.8 0.9 0.8 1" type="hfield" hfield="hill"/>    <!--geom conaffinity="1" condim="3" material="MatPlane" name="floor" pos="0 0 0" rgba="0.8 0.9 0.8 1" size="40 40 40" type="plane"/-->
    <body name="torso" pos="0 0 0.0">
      <camera name="track" mode="track" pos="0 -2.0 1.0" xyaxes="1 0 0 0. 0.5 1"/>
      <camera name="frontal" mode="fixed" pos="-1.6 0 1.9" xyaxes="0 -1 0 1.4 0 1"/>
      <geom name="torso_geom" pos="0 0 .04" size="0.12 0.06 0.02" mass="1" type="box" material="MatHex"/>
      <joint armature="0" damping="0" limited="false" margin="0.01" name="root" pos="0 0 0" type="free"/>

      <site name="b0" pos="0.12 0.01 0" axisangle="0.1 1 0 1.57" size="0.01" type="sphere" rgba="0.55 0.1 0.9 1.0"/>
      <site name="b1" pos="0.12 -0.01 0" axisangle="-0.1 1 0 1.57" size="0.01" type="sphere" rgba="0.55 0.1 0.9 1.0"/>

      <body name="thigh_fl" pos="0.12 0.08 0">
        <joint axis="1 0 0" name="thigh_x_fl" pos="0.0 0.0 0.0" range="-0.2 0.6" type="hinge"/>
        <joint axis="0 1 0" name="thigh_y_fl" pos="0.0 0.0 0.0" range="-0.6 0.6" type="hinge"/>
          <geom fromto="0.0 0.0 0.0 -0.03 0.0 -0.08" name="thigh_fl_geom" size="0.012" type="capsule" material="MatLeg"/>
          <body pos="-0.03 0 -0.08">
            <joint axis="0 1 0" name="leg_fl" pos="0.0 0.0 0.0" range="-0.6 0.6" type="hinge"/>
            <geom fromto="0.0 0.03 0.0 0.03 0.03 -0.06" name="leg_fl_geom" size="0.012" type="capsule" material="MatLeg" rgba="0.0 1.0 1.0 1.0"/>
            <site name="l0" pos="0.03 0.03 -0.06" size=".0125" type="sphere" rgba="1.0 1.0 1.0 1.0"/>
          </body>
      </body>

      <body name="thigh_rl" pos="-0.12 0.08 0">
        <joint axis="1 0 0" name="thigh_x_rl" pos="0.0 0.0 0.0" range="-0.2 0.6" type="hinge"/>
        <joint axis="0 -1 0" name="thigh_y_rl" pos="0.0 0.0 0.0" range="-0.6 0.6" type="hinge"/>
          <geom fromto="0.0 0.0 0.0 0.03 0.0 -0.08" name="thigh_rl_geom" size="0.012" type="capsule" material="MatLeg"/>
          <body pos="0.03 0 -0.08">
            <joint axis="0 -1 0" name="leg_rl" pos="0.0 0.0 0.0" range="-0.6 0.6" type="hinge"/>
            <geom fromto="0.0 0.03 0.0 -0.03 0.03 -0.06" name="leg_rl_geom" size="0.012" type="capsule" material="MatLeg"/>
            <site name="l1" pos="-0.03 0.03 -0.06" size=".0125" type="sphere" rgba="1.0 1.0 1.0 1.0"/>
          </body>
      </body>

      <body name="thigh_rr" pos="-0.12 -0.08 0">
        <joint axis="-1 0 0" name="thigh_x_rr" pos="0.0 0.0 0.0" range="-0.2 0.6" type="hinge"/>
        <joint axis="0 -1 0" name="thigh_y_rr" pos="0.0 0.0 0.0" range="-0.6 0.6" type="hinge"/>
          <geom fromto="0.0 0.0 0.0 0.03 0.0 -0.08" name="thigh_rr_geom" size="0.012" type="capsule" material="MatLeg"/>
          <body pos="0.03 0 -0.08">
            <joint axis="0 -1 0" name="leg_rr" pos="0.0 0.0 0.0" range="-0.6 0.6" type="hinge"/>
            <geom fromto="0.0 -0.03 0.0 -0.03 -0.03 -0.06" name="leg_rr_geom" size="0.012" type="capsule" material="MatLeg"/>
            <site name="l2" pos="-0.03 -0.03 -0.06" size=".0125" type="sphere" rgba="1.0 1.0 1.0 1.0"/>
          </body>
      </body>

      <body name="thigh_fr" pos="0.12 -0.08 0">
        <joint axis="-1 0 0" name="thigh_x_fr" pos="0.0 0.0 0.0" range="-0.2 0.6" type="hinge"/>
        <joint axis="0 1 0" name="thigh_y_fr" pos="0.0 0.0 0.0" range="-0.6 0.6" type="hinge"/>
          <geom fromto="0.0 0.0 0.0 -0.03 0.0 -0.08" name="thigh_fr_geom" size="0.012" type="capsule" material="MatLeg"/>
          <body pos="-0.03 0 -0.08">
            <joint axis="0 1 0" name="leg_fr" pos="0.0 0.0 0.0" range="-0.6 0.6" type="hinge"/>
            <geom fromto="0.0 -0.03 0.0 0.03 -0.03 -0.06" name="leg_fr_geom" size="0.012" type="capsule" material="MatLeg" rgba="0.0 1.0 1.0 1.0"/>
            <site name="l3" pos="0.03 -0.03 -0.06" size=".0125" type="sphere" rgba="1.0 1.0 1.0 1.0"/>
          </body>
      </body>


    </body>
  </worldbody>

  <sensor>
     <touch name="t0" site="l0" />
  </sensor>

  <sensor>
     <touch name="t1" site="l1" />
  </sensor>

  <sensor>
     <touch name="t2" site="l2" />
  </sensor>

  <sensor>
     <touch name="t3" site="l3" />
  </sensor>


  <sensor>
     <rangefinder name="r0" site="b0" />
  </sensor>

  <sensor>
     <rangefinder name="r1" site="b1" />
  </sensor>


  <actuator>
    <position joint="thigh_x_fl" kp="40"/>
    <position joint="thigh_y_fl" kp="40"/>
    <position joint="leg_fl" kp="40"/>
    <position joint="thigh_y_rl" kp="40"/>
    <position joint="thigh_x_rl" kp="40"/>
    <position joint="leg_rl" kp="40"/>
    <position joint="thigh_x_rr" kp="40"/>
    <position joint="thigh_y_rr" kp="40"/>
    <position joint="leg_rr" kp="40"/>
    <position joint="thigh_y_fr" kp="40"/>
    <position joint="thigh_x_fr" kp="40"/>
    <position joint="leg_fr" kp="40"/>
  </actuator>
</mujoco>
