
<mujoco model="centipede">
  <compiler angle="radian" coordinate="local" inertiafromgeom="true"/>

  <option integrator="RK4" timestep="0.02"/>
  <size nconmax="300"/>

  <default>
    <joint armature="0.1" damping="1" limited="true"/>
    <geom conaffinity="0" condim="3" density="25.0" friction="1.5 0.1 0.1" margin="0.01" rgba="0.8 0.6 0.4 1"/>
  </default>

  <asset>
    <texture builtin="gradient" height="100" rgb1="1 1 1" rgb2="0 0 0" type="skybox" width="100"/>
    <texture builtin="flat" height="1278" mark="cross" markrgb="1 1 1" name="texgeom" random="0.01" rgb1="0.8 0.6 0.4" rgb2="0.8 0.6 0.4" type="cube" width="127"/>
    <texture builtin="checker" height="100" name="texplane" rgb1="0 0 0" rgb2="0.8 0.8 0.8" type="2d" width="100"/>
    <material name="MatPlane" reflectance="0.5" shininess="1" specular="1" texrepeat="60 60" texture="texplane"/>
    <material name="geom" texture="texgeom" texuniform="true"/>
  </asset>

  <worldbody>
    <light cutoff="100" diffuse="1 1 1" dir="-0 0 -1.3" directional="true" exponent="1" pos="0 0 1.3" specular=".1 .1 .1"/>
    <geom conaffinity="1" condim="3" material="MatPlane" name="floor" pos="0 0 0" rgba="0.8 0.9 0.8 1" size="40 40 40" type="plane"/>
    <body name="torso_0" pos="0 0 0.75">
      <camera name="track" mode="track" pos="1 -5 2.7" xyaxes="1 0 0 0 0.5 1"/>
      <geom name="torsoGeom_0" pos="0 0 0" size="0.25" rgba="0 0 1 1" type="sphere" density="100"/>
      <joint armature="0" damping="0" limited="false" margin="0.01" name="root" pos="0 0 0" type="free"/>
      
      <body name="legbody_0" pos="0.0 -0.28 0">
        <joint axis="0 0 1" name="lefthip_0" pos="0.0 0.0 0.0" range="-0.65 0.65" type="hinge"/>
        <geom fromto="0.0 0.0 0.0 0.0 -0.28 0.0" name="legGeom_0" size="0.08" type="capsule" rgba=".0 .5 .5 1"/>
        <body pos="0 -0.28 0" name="frontFoot_0">
          <joint axis="1 0 0" name="ankle_0" pos="0.0 0.0 0.0" range="0.5 1.6" type="hinge"/>
          <geom fromto="0.0 0.0 0.0 0 -0.6 0.0" name="ankleGeom_0" size="0.08" type="capsule" rgba=".0 .5 .5 1"/>
        </body>
      </body>
      
      
      <body name="legbody_1" pos="0.0 0.28 0">
        <joint axis="0 0 1" name="righthip_1" pos="0.0 0.0 0.0" range="-0.65 0.65" type="hinge"/>
        <geom fromto="0.0 0.0 0.0 0.0 0.28 0.0" name="legGeom_1" size="0.08" type="capsule" rgba=".0 .5 .5 1"/>
        <body pos="0 0.28 0" name="frontFoot_1">
          <joint axis="-1 0 0" name="ankle_1" pos="0.0 0.0 0.0" range="0.5 1.6" type="hinge"/>
          <geom fromto="0.0 0.0 0.0 0 0.6 0.0" name="ankleGeom_1" size="0.08" type="capsule" rgba=".0 .5 .5 1"/>
        </body>
      </body>
      
      
      <body name="torso_1" pos="0.50 0 0">
        <geom name="torsoGeom_1" pos="0 0 0" size="0.25" type="sphere" density="100"/>
        <joint axis="0 0 1" name="body_1" pos="-0.25 0.0 0.0" range="-0.2 0.2" type="hinge"/>
        <joint axis="0 1 0" name="bodyupdown_1" pos="-0.25 0.0 0.0" range="-0.15 0.3" type="hinge"/>
      
        
        <body name="legbody_2" pos="0.0 -0.28 0">
          <joint axis="0 0 1" name="lefthip_2" pos="0.0 0.0 0.0" range="-0.65 0.65" type="hinge"/>
          <geom fromto="0.0 0.0 0.0 0.0 -0.28 0.0" name="legGeom_2" size="0.08" type="capsule" rgba=".0 .5 .5 1"/>
          <body pos="0 -0.28 0" name="frontFoot_2">
            <joint axis="1 0 0" name="ankle_2" pos="0.0 0.0 0.0" range="0.5 1.6" type="hinge"/>
            <geom fromto="0.0 0.0 0.0 0 -0.6 0.0" name="ankleGeom_2" size="0.08" type="capsule" rgba=".0 .5 .5 1"/>
          </body>
        </body>
        
        
        <body name="legbody_3" pos="0.0 0.28 0">
          <joint axis="0 0 1" name="righthip_3" pos="0.0 0.0 0.0" range="-0.65 0.65" type="hinge"/>
          <geom fromto="0.0 0.0 0.0 0.0 0.28 0.0" name="legGeom_3" size="0.08" type="capsule" rgba=".0 .5 .5 1"/>
          <body pos="0 0.28 0" name="frontFoot_3">
            <joint axis="-1 0 0" name="ankle_3" pos="0.0 0.0 0.0" range="0.5 1.6" type="hinge"/>
            <geom fromto="0.0 0.0 0.0 0 0.6 0.0" name="ankleGeom_3" size="0.08" type="capsule" rgba=".0 .5 .5 1"/>
          </body>
        </body>
        
        
        <body name="torso_2" pos="0.50 0 0">
          <geom name="torsoGeom_2" pos="0 0 0" size="0.25" type="sphere" density="100"/>
          <joint axis="0 0 1" name="body_2" pos="-0.25 0.0 0.0" range="-0.2 0.2" type="hinge"/>
          <joint axis="0 1 0" name="bodyupdown_2" pos="-0.25 0.0 0.0" range="-0.15 0.3" type="hinge"/>
        
          
          <body name="legbody_4" pos="0.0 -0.28 0">
            <joint axis="0 0 1" name="lefthip_4" pos="0.0 0.0 0.0" range="-0.65 0.65" type="hinge"/>
            <geom fromto="0.0 0.0 0.0 0.0 -0.28 0.0" name="legGeom_4" size="0.08" type="capsule" rgba=".0 .5 .5 1"/>
            <body pos="0 -0.28 0" name="frontFoot_4">
              <joint axis="1 0 0" name="ankle_4" pos="0.0 0.0 0.0" range="0.5 1.6" type="hinge"/>
              <geom fromto="0.0 0.0 0.0 0 -0.6 0.0" name="ankleGeom_4" size="0.08" type="capsule" rgba=".0 .5 .5 1"/>
            </body>
          </body>
          
          
          <body name="legbody_5" pos="0.0 0.28 0">
            <joint axis="0 0 1" name="righthip_5" pos="0.0 0.0 0.0" range="-0.65 0.65" type="hinge"/>
            <geom fromto="0.0 0.0 0.0 0.0 0.28 0.0" name="legGeom_5" size="0.08" type="capsule" rgba=".0 .5 .5 1"/>
            <body pos="0 0.28 0" name="frontFoot_5">
              <joint axis="-1 0 0" name="ankle_5" pos="0.0 0.0 0.0" range="0.5 1.6" type="hinge"/>
              <geom fromto="0.0 0.0 0.0 0 0.6 0.0" name="ankleGeom_5" size="0.08" type="capsule" rgba=".0 .5 .5 1"/>
            </body>
          </body>
          
          
          <body name="torso_3" pos="0.50 0 0">
            <geom name="torsoGeom_3" pos="0 0 0" size="0.25" type="sphere" density="100"/>
            <joint axis="0 0 1" name="body_3" pos="-0.25 0.0 0.0" range="-0.2 0.2" type="hinge"/>
            <joint axis="0 1 0" name="bodyupdown_3" pos="-0.25 0.0 0.0" range="-0.15 0.3" type="hinge"/>
          
            
            <body name="legbody_6" pos="0.0 -0.28 0">
              <joint axis="0 0 1" name="lefthip_6" pos="0.0 0.0 0.0" range="-0.65 0.65" type="hinge"/>
              <geom fromto="0.0 0.0 0.0 0.0 -0.28 0.0" name="legGeom_6" size="0.08" type="capsule" rgba=".0 .5 .5 1"/>
              <body pos="0 -0.28 0" name="frontFoot_6">
                <joint axis="1 0 0" name="ankle_6" pos="0.0 0.0 0.0" range="0.5 1.6" type="hinge"/>
                <geom fromto="0.0 0.0 0.0 0 -0.6 0.0" name="ankleGeom_6" size="0.08" type="capsule" rgba=".0 .5 .5 1"/>
              </body>
            </body>
            
            
            <body name="legbody_7" pos="0.0 0.28 0">
              <joint axis="0 0 1" name="righthip_7" pos="0.0 0.0 0.0" range="-0.65 0.65" type="hinge"/>
              <geom fromto="0.0 0.0 0.0 0.0 0.28 0.0" name="legGeom_7" size="0.08" type="capsule" rgba=".0 .5 .5 1"/>
              <body pos="0 0.28 0" name="frontFoot_7">
                <joint axis="-1 0 0" name="ankle_7" pos="0.0 0.0 0.0" range="0.5 1.6" type="hinge"/>
                <geom fromto="0.0 0.0 0.0 0 0.6 0.0" name="ankleGeom_7" size="0.08" type="capsule" rgba=".0 .5 .5 1"/>
              </body>
            </body>
            
            
            <body name="torso_4" pos="0.50 0 0">
              <geom name="torsoGeom_4" pos="0 0 0" size="0.25" type="sphere" density="100"/>
              <joint axis="0 0 1" name="body_4" pos="-0.25 0.0 0.0" range="-0.2 0.2" type="hinge"/>
              <joint axis="0 1 0" name="bodyupdown_4" pos="-0.25 0.0 0.0" range="-0.15 0.3" type="hinge"/>
            
              
              <body name="legbody_8" pos="0.0 -0.28 0">
                <joint axis="0 0 1" name="lefthip_8" pos="0.0 0.0 0.0" range="-0.65 0.65" type="hinge"/>
                <geom fromto="0.0 0.0 0.0 0.0 -0.28 0.0" name="legGeom_8" size="0.08" type="capsule" rgba=".0 .5 .5 1"/>
                <body pos="0 -0.28 0" name="frontFoot_8">
                  <joint axis="1 0 0" name="ankle_8" pos="0.0 0.0 0.0" range="0.5 1.6" type="hinge"/>
                  <geom fromto="0.0 0.0 0.0 0 -0.6 0.0" name="ankleGeom_8" size="0.08" type="capsule" rgba=".0 .5 .5 1"/>
                </body>
              </body>
              
              
              <body name="legbody_9" pos="0.0 0.28 0">
                <joint axis="0 0 1" name="righthip_9" pos="0.0 0.0 0.0" range="-0.65 0.65" type="hinge"/>
                <geom fromto="0.0 0.0 0.0 0.0 0.28 0.0" name="legGeom_9" size="0.08" type="capsule" rgba=".0 .5 .5 1"/>
                <body pos="0 0.28 0" name="frontFoot_9">
                  <joint axis="-1 0 0" name="ankle_9" pos="0.0 0.0 0.0" range="0.5 1.6" type="hinge"/>
                  <geom fromto="0.0 0.0 0.0 0 0.6 0.0" name="ankleGeom_9" size="0.08" type="capsule" rgba=".0 .5 .5 1"/>
                </body>
              </body>
              
              
              <body name="torso_5" pos="0.50 0 0">
                <geom name="torsoGeom_5" pos="0 0 0" size="0.25" type="sphere" density="100"/>
                <joint axis="0 0 1" name="body_5" pos="-0.25 0.0 0.0" range="-0.2 0.2" type="hinge"/>
                <joint axis="0 1 0" name="bodyupdown_5" pos="-0.25 0.0 0.0" range="-0.15 0.3" type="hinge"/>
              
                
                <body name="legbody_10" pos="0.0 -0.28 0">
                  <joint axis="0 0 1" name="lefthip_10" pos="0.0 0.0 0.0" range="-0.65 0.65" type="hinge"/>
                  <geom fromto="0.0 0.0 0.0 0.0 -0.28 0.0" name="legGeom_10" size="0.08" type="capsule" rgba=".0 .5 .5 1"/>
                  <body pos="0 -0.28 0" name="frontFoot_10">
                    <joint axis="1 0 0" name="ankle_10" pos="0.0 0.0 0.0" range="0.5 1.6" type="hinge"/>
                    <geom fromto="0.0 0.0 0.0 0 -0.6 0.0" name="ankleGeom_10" size="0.08" type="capsule" rgba=".0 .5 .5 1"/>
                  </body>
                </body>
                
                
                <body name="legbody_11" pos="0.0 0.28 0">
                  <joint axis="0 0 1" name="righthip_11" pos="0.0 0.0 0.0" range="-0.65 0.65" type="hinge"/>
                  <geom fromto="0.0 0.0 0.0 0.0 0.28 0.0" name="legGeom_11" size="0.08" type="capsule" rgba=".0 .5 .5 1"/>
                  <body pos="0 0.28 0" name="frontFoot_11">
                    <joint axis="-1 0 0" name="ankle_11" pos="0.0 0.0 0.0" range="0.5 1.6" type="hinge"/>
                    <geom fromto="0.0 0.0 0.0 0 0.6 0.0" name="ankleGeom_11" size="0.08" type="capsule" rgba=".0 .5 .5 1"/>
                  </body>
                </body>
                
                
                <body name="torso_6" pos="0.50 0 0">
                  <geom name="torsoGeom_6" pos="0 0 0" size="0.25" type="sphere" density="100"/>
                  <joint axis="0 0 1" name="body_6" pos="-0.25 0.0 0.0" range="-0.2 0.2" type="hinge"/>
                  <joint axis="0 1 0" name="bodyupdown_6" pos="-0.25 0.0 0.0" range="-0.15 0.3" type="hinge"/>
                
                  
                  <body name="legbody_12" pos="0.0 -0.28 0">
                    <joint axis="0 0 1" name="lefthip_12" pos="0.0 0.0 0.0" range="-0.65 0.65" type="hinge"/>
                    <geom fromto="0.0 0.0 0.0 0.0 -0.28 0.0" name="legGeom_12" size="0.08" type="capsule" rgba=".0 .5 .5 1"/>
                    <body pos="0 -0.28 0" name="frontFoot_12">
                      <joint axis="1 0 0" name="ankle_12" pos="0.0 0.0 0.0" range="0.5 1.6" type="hinge"/>
                      <geom fromto="0.0 0.0 0.0 0 -0.6 0.0" name="ankleGeom_12" size="0.08" type="capsule" rgba=".0 .5 .5 1"/>
                    </body>
                  </body>
                  
                  
                  <body name="legbody_13" pos="0.0 0.28 0">
                    <joint axis="0 0 1" name="righthip_13" pos="0.0 0.0 0.0" range="-0.65 0.65" type="hinge"/>
                    <geom fromto="0.0 0.0 0.0 0.0 0.28 0.0" name="legGeom_13" size="0.08" type="capsule" rgba=".0 .5 .5 1"/>
                    <body pos="0 0.28 0" name="frontFoot_13">
                      <joint axis="-1 0 0" name="ankle_13" pos="0.0 0.0 0.0" range="0.5 1.6" type="hinge"/>
                      <geom fromto="0.0 0.0 0.0 0 0.6 0.0" name="ankleGeom_13" size="0.08" type="capsule" rgba=".0 .5 .5 1"/>
                    </body>
                  </body>
                  
                </body>
              </body>
            </body>
          </body>
        </body>
      </body>

    </body>
  </worldbody>
  <actuator>
    <position  joint="lefthip_0" kp="40"/>
    <position  joint="ankle_0" kp="40"/>
    <position  joint="righthip_1" kp="40"/>
    <position  joint="ankle_1" kp="40"/>

    <position  joint="body_1" kp="40"/>
    <position  joint="bodyupdown_1" kp="40"/>
    <position  joint="lefthip_2" kp="40"/>
    <position  joint="ankle_2" kp="40"/>
    <position  joint="righthip_3" kp="40"/>
    <position  joint="ankle_3" kp="40"/>
    
    <position  joint="body_2" kp="40"/>
    <position  joint="bodyupdown_2" kp="40"/>
    <position  joint="lefthip_4" kp="40"/>
    <position  joint="ankle_4" kp="40"/>
    <position  joint="righthip_5" kp="40"/>
    <position  joint="ankle_5" kp="40"/>
    
    <position  joint="body_3" kp="40"/>
    <position  joint="bodyupdown_3" kp="40"/>
    <position  joint="lefthip_6" kp="40"/>
    <position  joint="ankle_6" kp="40"/>
    <position  joint="righthip_7" kp="40"/>
    <position  joint="ankle_7" kp="40"/>

    <position  joint="body_4" kp="40"/>
    <position  joint="bodyupdown_4" kp="40"/>
    <position  joint="lefthip_8" kp="40"/>
    <position  joint="ankle_8" kp="40"/>
    <position  joint="righthip_9" kp="40"/>
    <position  joint="ankle_9" kp="40"/>
    
    <position  joint="body_5" kp="40"/>
    <position  joint="bodyupdown_5" kp="40"/>
    <position  joint="lefthip_10" kp="40"/>
    <position  joint="ankle_10" kp="40"/>
    <position  joint="righthip_11" kp="40"/>
    <position  joint="ankle_11" kp="40"/>
    
    <position  joint="body_6" kp="40"/>
    <position  joint="bodyupdown_6" kp="40"/>
    <position  joint="lefthip_12" kp="40"/>
    <position  joint="ankle_12" kp="40"/>
    <position  joint="righthip_13" kp="40"/>
    <position  joint="ankle_13" kp="40"/>
    
  </actuator>
  <custom>
    <numeric data="0.0 0.0 0.55 1.0 0.0 0.0 0.0 0.0 -1.0 0.0 1.0 0.0 -1.0 0.0 1.0 0.0 -1.0 0.0 1.0 0.0 -1.0 0.0 1.0 0.0 -1.0 0.0 1.0 0.0 -1.0 0.0 1.0 0.0 -1.0 0.0 1.0" name="init_qpos"/>
  </custom>

</mujoco>
